<?xml version="1.0" ?>
<robot name="assembly_v2" xmlns:xacro="http://www.ros.org/wiki/xacro">

<xacro:include filename="$(find assembly_v2_description)/urdf/materials.xacro" />
<xacro:include filename="$(find assembly_v2_description)/urdf/assembly_v2.trans" />
<xacro:include filename="$(find assembly_v2_description)/urdf/assembly_v2.gazebo" />
<link name="base_link">
  <inertial>
    <origin xyz="0.0006033383004041557 -4.06252211853132e-17 0.0024899443616599303" rpy="0 0 0"/>
    <mass value="3.51482808"/>
    <inertia ixx="0.026497" iyy="0.026243" izz="0.052725" ixy="-0.0" iyz="0.0" ixz="-4e-06"/>
  </inertial>
  <visual>
    <origin xyz="0 0 0" rpy="0 0 0"/>
    <geometry>
      <mesh filename="package://assembly_v2_description/meshes/base_link.stl" scale="0.001 0.001 0.001"/>
    </geometry>
    <material name="mdf_board"/>
  </visual>
  <collision>
    <origin xyz="0 0 0" rpy="0 0 0"/>
    <geometry>
      <mesh filename="package://assembly_v2_description/meshes/base_link.stl" scale="0.001 0.001 0.001"/>
    </geometry>
  </collision>
</link>

<link name="tower_1">
  <inertial>
    <origin xyz="4.514444373882043e-14 -0.028102155900764397 0.06964033102003142" rpy="0 0 0"/>
    <mass value="0.6072200391977587"/>
    <inertia ixx="0.001713" iyy="0.001482" izz="0.000706" ixy="-0.0" iyz="5.3e-05" ixz="0.0"/>
  </inertial>
  <visual>
    <origin xyz="0.12 -0.0268 -0.005" rpy="0 0 0"/>
    <geometry>
      <mesh filename="package://assembly_v2_description/meshes/tower_1.stl" scale="0.001 0.001 0.001"/>
    </geometry>
    <material name="nylon_66_bianco"/>
  </visual>
  <collision>
    <origin xyz="0.12 -0.0268 -0.005" rpy="0 0 0"/>
    <geometry>
      <mesh filename="package://assembly_v2_description/meshes/tower_1.stl" scale="0.001 0.001 0.001"/>
    </geometry>
  </collision>
</link>

<link name="arm_pitch_1">
  <inertial>
    <origin xyz="2.7749514237535022e-05 0.0025971752014119914 -0.007626953343667947" rpy="0 0 0"/>
    <mass value="0.008822962792787544"/>
    <inertia ixx="1e-06" iyy="1e-06" izz="0.0" ixy="0.0" iyz="-0.0" ixz="0.0"/>
  </inertial>
  <visual>
    <origin xyz="0.12 0.0268 -0.155" rpy="0 0 0"/>
    <geometry>
      <mesh filename="package://assembly_v2_description/meshes/arm_pitch_1.stl" scale="0.001 0.001 0.001"/>
    </geometry>
    <material name="opaque2476666"/>
  </visual>
  <collision>
    <origin xyz="0.12 0.0268 -0.155" rpy="0 0 0"/>
    <geometry>
      <mesh filename="package://assembly_v2_description/meshes/arm_pitch_1.stl" scale="0.001 0.001 0.001"/>
    </geometry>
  </collision>
</link>

<link name="bearing_1">
  <inertial>
    <origin xyz="7.463474283042615e-14 -0.0030000000000001067 -2.220446049250313e-16" rpy="0 0 0"/>
    <mass value="0.008917188217734908"/>
    <inertia ixx="0.0" iyy="0.0" izz="0.0" ixy="0.0" iyz="-0.0" ixz="0.0"/>
  </inertial>
  <visual>
    <origin xyz="0.12 -0.0328 -0.155" rpy="0 0 0"/>
    <geometry>
      <mesh filename="package://assembly_v2_description/meshes/bearing_1.stl" scale="0.001 0.001 0.001"/>
    </geometry>
    <material name="cromo"/>
  </visual>
  <collision>
    <origin xyz="0.12 -0.0328 -0.155" rpy="0 0 0"/>
    <geometry>
      <mesh filename="package://assembly_v2_description/meshes/bearing_1.stl" scale="0.001 0.001 0.001"/>
    </geometry>
  </collision>
</link>

<link name="bracket_pitch_1">
  <inertial>
    <origin xyz="6.529499163576702e-14 -0.005354418300046206 -0.008578876290632531" rpy="0 0 0"/>
    <mass value="0.04031781214938913"/>
    <inertia ixx="8e-06" iyy="1e-05" izz="3e-06" ixy="0.0" iyz="-0.0" ixz="-0.0"/>
  </inertial>
  <visual>
    <origin xyz="0.12 -0.0268 -0.155" rpy="0 0 0"/>
    <geometry>
      <mesh filename="package://assembly_v2_description/meshes/bracket_pitch_1.stl" scale="0.001 0.001 0.001"/>
    </geometry>
    <material name="nylon_66_bianco"/>
  </visual>
  <collision>
    <origin xyz="0.12 -0.0268 -0.155" rpy="0 0 0"/>
    <geometry>
      <mesh filename="package://assembly_v2_description/meshes/bracket_pitch_1.stl" scale="0.001 0.001 0.001"/>
    </geometry>
  </collision>
</link>

<link name="SP_1">
  <inertial>
    <origin xyz="4.2478746313801e-06 -0.02050934968537407 9.580573711495677e-05" rpy="0 0 0"/>
    <mass value="0.05033660873275774"/>
    <inertia ixx="1.4e-05" iyy="9e-06" izz="8e-06" ixy="-0.0" iyz="0.0" ixz="-0.0"/>
  </inertial>
  <visual>
    <origin xyz="0.12 -0.0213 -0.1448" rpy="0 0 0"/>
    <geometry>
      <mesh filename="package://assembly_v2_description/meshes/SP_1.stl" scale="0.001 0.001 0.001"/>
    </geometry>
    <material name="opaque636363"/>
  </visual>
  <collision>
    <origin xyz="0.12 -0.0213 -0.1448" rpy="0 0 0"/>
    <geometry>
      <mesh filename="package://assembly_v2_description/meshes/SP_1.stl" scale="0.001 0.001 0.001"/>
    </geometry>
  </collision>
</link>

<link name="servo_bracket_1">
  <inertial>
    <origin xyz="0.023519811176005392 0.0008029483681285072 -0.024919322940149147" rpy="0 0 0"/>
    <mass value="0.11882042598616296"/>
    <inertia ixx="6.6e-05" iyy="7.6e-05" izz="2.5e-05" ixy="4e-06" iyz="1e-06" ixz="-0.0"/>
  </inertial>
  <visual>
    <origin xyz="0.1249 0.0062 -0.1691" rpy="0 0 0"/>
    <geometry>
      <mesh filename="package://assembly_v2_description/meshes/servo_bracket_1.stl" scale="0.001 0.001 0.001"/>
    </geometry>
    <material name="nylon_66_bianco"/>
  </visual>
  <collision>
    <origin xyz="0.1249 0.0062 -0.1691" rpy="0 0 0"/>
    <geometry>
      <mesh filename="package://assembly_v2_description/meshes/servo_bracket_1.stl" scale="0.001 0.001 0.001"/>
    </geometry>
  </collision>
</link>

<link name="SR_1">
  <inertial>
    <origin xyz="-0.006971398812242138 0.004899992393469853 -0.024229170990020116" rpy="0 0 0"/>
    <mass value="0.05027212799160954"/>
    <inertia ixx="9e-06" iyy="1.4e-05" izz="8e-06" ixy="-0.0" iyz="0.0" ixz="-0.0"/>
  </inertial>
  <visual>
    <origin xyz="0.0825 0.00765 -0.1691" rpy="0 0 0"/>
    <geometry>
      <mesh filename="package://assembly_v2_description/meshes/SR_1.stl" scale="0.001 0.001 0.001"/>
    </geometry>
    <material name="opaque636363"/>
  </visual>
  <collision>
    <origin xyz="0.0825 0.00765 -0.1691" rpy="0 0 0"/>
    <geometry>
      <mesh filename="package://assembly_v2_description/meshes/SR_1.stl" scale="0.001 0.001 0.001"/>
    </geometry>
  </collision>
</link>

<link name="arm_roll_1">
  <inertial>
    <origin xyz="2.8778251977418234e-06 2.8070368289890603e-05 -0.007626301102671734" rpy="0 0 0"/>
    <mass value="0.00882263111091566"/>
    <inertia ixx="1e-06" iyy="1e-06" izz="0.0" ixy="-0.0" iyz="0.0" ixz="0.0"/>
  </inertial>
  <visual>
    <origin xyz="0.0645 0.00275 -0.155" rpy="0 0 0"/>
    <geometry>
      <mesh filename="package://assembly_v2_description/meshes/arm_roll_1.stl" scale="0.001 0.001 0.001"/>
    </geometry>
    <material name="opaque2476666"/>
  </visual>
  <collision>
    <origin xyz="0.0645 0.00275 -0.155" rpy="0 0 0"/>
    <geometry>
      <mesh filename="package://assembly_v2_description/meshes/arm_roll_1.stl" scale="0.001 0.001 0.001"/>
    </geometry>
  </collision>
</link>

<link name="bracket_roll_1">
  <inertial>
    <origin xyz="0.02121188618831852 1.0232715173287554e-07 -0.006535203876488066" rpy="0 0 0"/>
    <mass value="0.10024421441001274"/>
    <inertia ixx="9.9e-05" iyy="7.3e-05" izz="0.000159" ixy="0.0" iyz="-0.0" ixz="-1e-06"/>
  </inertial>
  <visual>
    <origin xyz="0.0619 0.00275 -0.155" rpy="0 0 0"/>
    <geometry>
      <mesh filename="package://assembly_v2_description/meshes/bracket_roll_1.stl" scale="0.001 0.001 0.001"/>
    </geometry>
    <material name="nylon_66_bianco"/>
  </visual>
  <collision>
    <origin xyz="0.0619 0.00275 -0.155" rpy="0 0 0"/>
    <geometry>
      <mesh filename="package://assembly_v2_description/meshes/bracket_roll_1.stl" scale="0.001 0.001 0.001"/>
    </geometry>
  </collision>
</link>

<link name="glass_plate_1">
  <inertial>
    <origin xyz="-8.743006318923108e-16 0.05000030135040751 0.0015000517457916251" rpy="0 0 0"/>
    <mass value="0.16676383619521307"/>
    <inertia ixx="0.000313" iyy="0.000402" izz="0.000714" ixy="-0.0" iyz="-0.0" ixz="-0.0"/>
  </inertial>
  <visual>
    <origin xyz="-0.0281 0.05275 -0.153" rpy="0 0 0"/>
    <geometry>
      <mesh filename="package://assembly_v2_description/meshes/glass_plate_1.stl" scale="0.001 0.001 0.001"/>
    </geometry>
    <material name="vetro_finestra"/>
  </visual>
  <collision>
    <origin xyz="-0.0281 0.05275 -0.153" rpy="0 0 0"/>
    <geometry>
      <mesh filename="package://assembly_v2_description/meshes/glass_plate_1.stl" scale="0.001 0.001 0.001"/>
    </geometry>
  </collision>
</link>

<link name="rubber_coating_1">
  <inertial>
    <origin xyz="-0.07499999999999994 3.0135371253568397e-07 0.0005000000000002225" rpy="0 0 0"/>
    <mass value="0.06075000000000086"/>
    <inertia ixx="0.000114" iyy="0.000114" izz="0.000228" ixy="-0.0" iyz="-0.0" ixz="0.0"/>
  </inertial>
  <visual>
    <origin xyz="-0.1131 0.00275 -0.156" rpy="0 0 0"/>
    <geometry>
      <mesh filename="package://assembly_v2_description/meshes/rubber_coating_1.stl" scale="0.001 0.001 0.001"/>
    </geometry>
    <material name="rivestimento_a_polvere_nero"/>
  </visual>
  <collision>
    <origin xyz="-0.1131 0.00275 -0.156" rpy="0 0 0"/>
    <geometry>
      <mesh filename="package://assembly_v2_description/meshes/rubber_coating_1.stl" scale="0.001 0.001 0.001"/>
    </geometry>
  </collision>
</link>

<joint name="Rigido 5" type="fixed">
  <origin xyz="-0.12 0.0268 0.005" rpy="0 0 0"/>
  <parent link="base_link"/>
  <child link="tower_1"/>
</joint>

<joint name="Rigido 6" type="fixed">
  <origin xyz="0.0 -0.0536 0.15" rpy="0 0 0"/>
  <parent link="tower_1"/>
  <child link="arm_pitch_1"/>
</joint>

<joint name="Rigido 7" type="fixed">
  <origin xyz="0.0 0.006 0.15" rpy="0 0 0"/>
  <parent link="tower_1"/>
  <child link="bearing_1"/>
</joint>

<joint name="Rivoluzione 8" type="continuous">
  <origin xyz="0.0 -0.006 0.0" rpy="0 0 0"/>
  <parent link="bearing_1"/>
  <child link="bracket_pitch_1"/>
  <axis xyz="0.0 -1.0 -0.0"/>
</joint>

<joint name="Rigido 9" type="fixed">
  <origin xyz="0.0 -0.0055 -0.0102" rpy="0 0 0"/>
  <parent link="bracket_pitch_1"/>
  <child link="SP_1"/>
</joint>

<joint name="Rigido 10" type="fixed">
  <origin xyz="-0.0049 -0.0275 0.0243" rpy="0 0 0"/>
  <parent link="SP_1"/>
  <child link="servo_bracket_1"/>
</joint>

<joint name="Rigido 11" type="fixed">
  <origin xyz="0.0424 -0.00145 0.0" rpy="0 0 0"/>
  <parent link="servo_bracket_1"/>
  <child link="SR_1"/>
</joint>

<joint name="Rivoluzione 12" type="continuous">
  <origin xyz="0.018 0.0049 -0.0141" rpy="0 0 0"/>
  <parent link="SR_1"/>
  <child link="arm_roll_1"/>
  <axis xyz="1.0 0.0 0.0"/>
</joint>

<joint name="Rigido 13" type="fixed">
  <origin xyz="0.0026 0.0 0.0" rpy="0 0 0"/>
  <parent link="arm_roll_1"/>
  <child link="bracket_roll_1"/>
</joint>

<joint name="Rigido 14" type="fixed">
  <origin xyz="0.09 -0.05 -0.002" rpy="0 0 0"/>
  <parent link="bracket_roll_1"/>
  <child link="glass_plate_1"/>
</joint>

<joint name="Rigido 15" type="fixed">
  <origin xyz="0.085 0.05 0.003" rpy="0 0 0"/>
  <parent link="glass_plate_1"/>
  <child link="rubber_coating_1"/>
</joint>

</robot>
